<robot
  name="LR Mate-200iD7LC.SLDASM">
  <link
    name="base_link">
    <inertial>
      <origin
        xyz="-0.0068267 -0.00032171 0.080423"
        rpy="0 0 0" />
      <mass
        value="4.8533E-10" />
      <inertia
        ixx="2.1987E-12"
        ixy="-1.185E-14"
        ixz="1.4301E-14"
        iyy="2.3829E-12"
        iyz="-3.0601E-15"
        izz="2.2801E-12" />
    </inertial>
    <visual>
      <origin
        xyz="0 0 0"
        rpy="0 0 0" />
      <geometry>
        <mesh
          filename="package://LR Mate-200iD7LC.SLDASM/meshes/base_link.stl" />
      </geometry>
      <material
        name="">
        <color
          rgba="1 1 1 1" />
      </material>
    </visual>
    <collision>
      <origin
        xyz="0 0 0"
        rpy="0 0 0" />
      <geometry>
        <mesh
          filename="package://LR Mate-200iD7LC.SLDASM/meshes/base_link.stl" />
      </geometry>
    </collision>
  </link>
  <link
    name="link_1">
    <inertial>
      <origin
        xyz="-5.6272E-17 1.5421E-17 -0.169"
        rpy="0 0 0" />
      <mass
        value="0" />
      <inertia
        ixx="0"
        ixy="0"
        ixz="0"
        iyy="0"
        iyz="0"
        izz="0" />
    </inertial>
    <visual>
      <origin
        xyz="0 0 0"
        rpy="0 0 0" />
      <geometry>
        <mesh
          filename="package://LR Mate-200iD7LC.SLDASM/meshes/link_1.stl" />
      </geometry>
      <material
        name="">
        <color
          rgba="1 1 1 1" />
      </material>
    </visual>
    <collision>
      <origin
        xyz="0 0 0"
        rpy="0 0 0" />
      <geometry>
        <mesh
          filename="package://LR Mate-200iD7LC.SLDASM/meshes/link_1.stl" />
      </geometry>
    </collision>
  </link>
  <joint
    name="joint_1"
    type="revolute">
    <origin
      xyz="0 0 0.169"
      rpy="0 0 0" />
    <parent
      link="base_link" />
    <child
      link="link_1" />
    <axis
      xyz="0 0 1" />
    <limit
      effort="0"
      velocity="0" />
  </joint>
  <link
    name="link_2">
    <inertial>
      <origin
        xyz="0.17556 0.0015476 -0.0096684"
        rpy="0 0 0" />
      <mass
        value="7.9665E-10" />
      <inertia
        ixx="3.5822E-12"
        ixy="8.8459E-14"
        ixz="2.726E-13"
        iyy="1.7474E-11"
        iyz="-9.5863E-15"
        izz="1.957E-11" />
    </inertial>
    <visual>
      <origin
        xyz="0 0 0"
        rpy="0 0 0" />
      <geometry>
        <mesh
          filename="package://LR Mate-200iD7LC.SLDASM/meshes/link_2.stl" />
      </geometry>
      <material
        name="">
        <color
          rgba="1 1 1 1" />
      </material>
    </visual>
    <collision>
      <origin
        xyz="0 0 0"
        rpy="0 0 0" />
      <geometry>
        <mesh
          filename="package://LR Mate-200iD7LC.SLDASM/meshes/link_2.stl" />
      </geometry>
    </collision>
  </link>
  <joint
    name="joint_2"
    type="revolute">
    <origin
      xyz="0.05 0.001 0.1601"
      rpy="0 -1.5708 0" />
    <parent
      link="link_1" />
    <child
      link="link_2" />
    <axis
      xyz="0 -1 0" />
    <limit
      effort="0"
      velocity="0" />
  </joint>
  <link
    name="link_3">
    <inertial>
      <origin
        xyz="0.017646 0.0082385 0.00068041"
        rpy="0 0 0" />
      <mass
        value="2.3943E-10" />
      <inertia
        ixx="7.2607E-13"
        ixy="-7.6136E-14"
        ixz="-6.6486E-15"
        iyy="6.3347E-13"
        iyz="-4.9519E-15"
        izz="7.3283E-13" />
    </inertial>
    <visual>
      <origin
        xyz="0 0 0"
        rpy="0 0 0" />
      <geometry>
        <mesh
          filename="package://LR Mate-200iD7LC.SLDASM/meshes/link_3.stl" />
      </geometry>
      <material
        name="">
        <color
          rgba="1 1 1 1" />
      </material>
    </visual>
    <collision>
      <origin
        xyz="0 0 0"
        rpy="0 0 0" />
      <geometry>
        <mesh
          filename="package://LR Mate-200iD7LC.SLDASM/meshes/link_3.stl" />
      </geometry>
    </collision>
  </link>
  <joint
    name="joint_3"
    type="revolute">
    <origin
      xyz="0.44 -0.001 0"
      rpy="1.5708 0 0" />
    <parent
      link="link_2" />
    <child
      link="link_3" />
    <axis
      xyz="0 0 1" />
    <limit
      effort="0"
      velocity="0" />
  </joint>
  <link
    name="link_4">
    <inertial>
      <origin
        xyz="-0.0040166 -0.00028061 0.15002"
        rpy="0 0 0" />
      <mass
        value="2.8909E-10" />
      <inertia
        ixx="2.6679E-12"
        ixy="4.2268E-16"
        ixz="2.4382E-14"
        iyy="2.7121E-12"
        iyz="-6.33E-16"
        izz="4.8164E-13" />
    </inertial>
    <visual>
      <origin
        xyz="0 0 0"
        rpy="0 0 0" />
      <geometry>
        <mesh
          filename="package://LR Mate-200iD7LC.SLDASM/meshes/link_4.stl" />
      </geometry>
      <material
        name="">
        <color
          rgba="1 1 1 1" />
      </material>
    </visual>
    <collision>
      <origin
        xyz="0 0 0"
        rpy="0 0 0" />
      <geometry>
        <mesh
          filename="package://LR Mate-200iD7LC.SLDASM/meshes/link_4.stl" />
      </geometry>
    </collision>
  </link>
  <joint
    name="joint_4"
    type="revolute">
    <origin
      xyz="0.035055 0.0885 0.0034374"
      rpy="1.5708 1.5708 0" />
    <parent
      link="link_3" />
    <child
      link="link_4" />
    <axis
      xyz="0 0 1" />
    <limit
      effort="0"
      velocity="0" />
  </joint>
  <link
    name="link_5">
    <inertial>
      <origin
        xyz="-5.397E-05 0.022886 0.002714"
        rpy="0 0 0" />
      <mass
        value="4.9068E-11" />
      <inertia
        ixx="7.3958E-14"
        ixy="-2.2138E-17"
        ixz="1.5328E-18"
        iyy="3.3325E-14"
        iyz="3.4869E-15"
        izz="7.6276E-14" />
    </inertial>
    <visual>
      <origin
        xyz="0 0 0"
        rpy="0 0 0" />
      <geometry>
        <mesh
          filename="package://LR Mate-200iD7LC.SLDASM/meshes/link_5.stl" />
      </geometry>
      <material
        name="">
        <color
          rgba="0.79216 0.81961 0.93333 1" />
      </material>
    </visual>
    <collision>
      <origin
        xyz="0 0 0"
        rpy="0 0 0" />
      <geometry>
        <mesh
          filename="package://LR Mate-200iD7LC.SLDASM/meshes/link_5.stl" />
      </geometry>
    </collision>
  </link>
  <joint
    name="joint_5"
    type="revolute">
    <origin
      xyz="0.00075 0 0.3299"
      rpy="1.5708 0 -1.5708" />
    <parent
      link="link_4" />
    <child
      link="link_5" />
    <axis
      xyz="0 0 1" />
    <limit
      effort="0"
      velocity="0" />
  </joint>
  <link
    name="link_6">
    <inertial>
      <origin
        xyz="-0.00035712 8.6736E-19 -0.0030153"
        rpy="0 0 0" />
      <mass
        value="0.0051957" />
      <inertia
        ixx="6.7926E-07"
        ixy="-8.3001E-23"
        ixz="2.8347E-11"
        iyy="6.4938E-07"
        iyz="-4.1848E-23"
        izz="1.2977E-06" />
    </inertial>
    <visual>
      <origin
        xyz="0 0 0"
        rpy="0 0 0" />
      <geometry>
        <mesh
          filename="package://LR Mate-200iD7LC.SLDASM/meshes/link_6.stl" />
      </geometry>
      <material
        name="">
        <color
          rgba="0.79216 0.81961 0.93333 1" />
      </material>
    </visual>
    <collision>
      <origin
        xyz="0 0 0"
        rpy="0 0 0" />
      <geometry>
        <mesh
          filename="package://LR Mate-200iD7LC.SLDASM/meshes/link_6.stl" />
      </geometry>
    </collision>
  </link>
  <joint
    name="joint_6"
    type="revolute">
    <origin
      xyz="0 0.092 0"
      rpy="-1.5708 0 -1.1102E-16" />
    <parent
      link="link_5" />
    <child
      link="link_6" />
    <axis
      xyz="0 0 1" />
    <limit
      effort="0"
      velocity="0" />
  </joint>
</robot>